@{
from math import sin, cos, radians
size_x = metadata["scale"] * 20 / metadata["horizontal_chunks"]
size_y = metadata["scale"] * 20 / metadata["vertical_chunks"]
inter_ray_angle = 360 / rangefinders
affordance = 0.1
pr, pg, pb = map_color
}@
<mujoco model="MuJoCo Model">
  <compiler autolimits="true" texturedir="icons/"/>
  <option timestep="0.0075"/>
  <visual>
    <rgba rangefinder="1.0 1.0 0.0 0.075"/>
    <headlight ambient="0.5 0.5 0.5"/>
    <quality shadowsize="4096"/>
  </visual>
  <statistic meansize="0.509902" extent="1.6099" center="0 0 0.704951"/>
  <default class="main">
    <default class="suspension">
      <joint type="slide" stiffness="10" damping="0.5" armature="0.01" range="-0.01 -0.001"/>
    </default>
    <joint  damping="0.03"/>
    <default class="wheel">
      <geom solimp="0 0.95 0.001 0.5 2" size="0.03 0.01 0" type="cylinder"/>
    </default>
    <default class="decor">
      <site type="box"/>
    </default>
    <default class="tester">
    </default>
  </default>
  <asset>
    <material name="transparent" rgba="0 0 0 0"/>
@[for i, car in enumerate(cars) ]@
@{
r1, g1, b1 = [x/255 for x in car['primary']]
r2, g2, b2 = [x/255 for x in car['secondary']]
}@
    <!-- <texture type="cube" name="car #@i icon"  file="@car['icon']"/> -->
    <texture type="2d" name="car #@i icon"  file="@car['icon']" />
    <!-- <material name="car #@i icon" texture="car #@i icon" reflectance="1"/> -->
    <material name="car #@i icon" rgba="0.8 0.8 0.8 1.0" texture="car #@i icon" reflectance="1"/>
    <material name="car #@i primary"   rgba="@r1 @g1 @b1 1.0"/>
    <material name="car #@i secondary" rgba="@r2 @g2 @b2 1.0"/>
    <material name="car #@i body"      rgba="0.1 0.1 0.1 1.0"/>
    <material name="car #@i wheel"     rgba="0.1 0.1 0.1 1.0"/>
@[end for]@
    <texture type="2d" name="grid" builtin="checker" rgb1="@pr @pg @pb" rgb2="1 1 1" width="512" height="512"/>
    <material name="plane" reflectance="0.1" rgba="@(pr/3) @(pg/3) @(pb/3) 1"/>
    <material name="grid" texture="grid" texuniform="true" reflectance="0"/>
    <mesh name="chasis" vertex="9 2 0 -10 10 10 9 -2 0 10 3 -10 10 -3 -10 -8 10 -10 -10 -10 10 -8 -10 -10 -5 0 20" scale="0.01 0.006 0.0015"/>
@[for (x,y) in metadata["chunks"] ]@
    <hfield name="map-@(f'{x:03}x{y:03}')" file="chunks/@(f'{x:03}x{y:03}.png')" size="@(size_x/2) @(size_y/2) @(0.15 + affordance) 0.0001"/>
@[end for]@
  </asset>
  <worldbody>
@[for (x,y) in metadata["chunks"] ]@
    <geom conaffinity="5" contype="4" material="grid" type="hfield" hfield="map-@(f'{x:03}x{y:03}')" pos="@(size_x * x) @(-size_y * y) @(-affordance)"/>
@[end for]@
    <geom  conaffinity="3" contype="1" name="plane" material="plane" size="300 300 0.1" pos="0 0 0.01" type="plane" rgba="0.3 0 0 1"/>
    <light pos="4.5 -3.0 3" dir="0 0 -1" diffuse="0.5 0.5 0.5"/>
@[for i, car in enumerate(cars)]@
@{
# primary and secondary colors
}@
    <body name="car #@i" pos="@car['x'] @car['y'] @car['z']">
      <joint name="car #@i" type="free"  damping="0"/>
      <light name="top light #@i" pos="0 0 2" dir="0 0 -1" diffuse="0.4 0.4 0.4" mode="trackcom"/>
      <light name="front light #@i" pos="0.1 0 0.02" dir="0.894427 0 -0.447214" diffuse="1 1 1"/>
      <geom name="chasis #@i" type="mesh" mesh="chasis" material="car #@i primary"/>
      <site name="car #@i accelerometer" euler="0 0 -90" rgba="0 0 0 0"/>
      <site name="car #@i gyroscope" euler="0 0 -90" rgba="0 0 0 0"/>
@{
# rangefinder origin
rx, ry, rz = -0.0525, 0.000, 0.030
# lidar model radius and height
lr = 0.030
lh = 0.015
}@
       <geom density="2000" name="car #@i lidar" type="cylinder" size="@lr @lh 0.01" pos="@rx @ry @(rz - lh/2)" material="car #@i body"/>
       <site material="car #@i icon" type="ellipsoid" euler="0 0 -90" size="@(lr*0.9) @(lr*0.9) 0.0075" pos="@rx @ry @(rz + lh/2 - 0.0005)"/>
       <site material="car #@i secondary" type="ellipsoid" euler="0 0 -90" size="@(lr*1.1) @(lr*1.1) 0.0100" pos="@rx @ry @rz"/>
@[for j in range(rangefinders) ]@ 
@{
theta = -radians(inter_ray_angle*j - 90)
}@
      <site name="rangefinder #@i.#@j" pos="@(rx + lr*sin(theta)) @(lr * cos(theta)) @rz" euler="90 @(inter_ray_angle*j - 90) 0" rgba="0 0 0 0"/>
@[end for]@
@{
mw = 0.5
}@
      <body pos="0.090 0 -0.01">
        <joint class="suspension"/>
        <joint type="ball"/>
        <!-- <site size="0.035" rgba="0.7 0.7 0.7 0.2"/> -->
        <geom size="0.035" rgba="0.7 0.7 0.7 0.0" contype="0" conaffinity="4" mass="0.00000001" name="front softener #@i"/>
      </body>
      <geom name="front wheel #@i" mass="@(mw / 3)" material="car #@i wheel" size="0.015" pos="0.08 0 -0.015" condim="1" priority="1"/>
      <body name="left wheel #@i" pos="-0.07 0.06 0" quat="0.707107 -0.707107 0 0">
        <joint class="suspension" axis="0 -1 0"/>
        <body>
          <joint type="ball"/>
          <!-- <site size="0.035" rgba="0.7 0.7 0.7 0.2"/> -->
          <geom size="0.035" rgba="0.7 0.7 0.7 0.0" contype="0" conaffinity="4" mass="0.00000001" name="left softener #@i"/>
        </body>
        <joint name="left #@i" pos="0 0 0" axis="0 0 1"/>
        <geom name="left wheel #@i" material="car #@i wheel" mass="@(mw / 3)" class="wheel"/>
        <site class="decor" material="car #@i secondary" pos="0 0 0" size="0.006 0.025 0.012"/>
        <site class="decor" material="car #@i secondary" pos="0 0 0" size="0.025 0.006 0.012"/>
      </body>
      <body pos="-0.07 -0.06 0" quat="0.707107 -0.707107 0 0">
        <joint class="suspension"  axis="0 -1 0"/>
        <body>
          <joint type="ball"/>
          <!-- <site size="0.035" rgba="0.7 0.7 0.7 0.2"/> -->
          <geom size="0.035" rgba="0.7 0.7 0.7 0.0" contype="0" conaffinity="4" mass="0.00000001" name="right softener #@i"/>
        </body>
        <joint name="right #@i" pos="0 0 0" axis="0 0 1"/>
        <geom name="right wheel #@i" material="car #@i wheel" mass="@(mw / 3)" class="wheel"/>
        <site class="decor" material="car #@i secondary" pos="0 0 0" size="0.006 0.025 0.012"/>
        <site class="decor" material="car #@i secondary" pos="0 0 0" size="0.025 0.006 0.012"/>
      </body>
    </body>
@[end for]@
  </worldbody>
  <tendon>
@[for i, car in enumerate(cars)]@
    <fixed name="forward #@i">
      <joint joint="left #@i" coef="0.5"/>
      <joint joint="right #@i" coef="0.5"/>
    </fixed>
    <fixed name="turn #@i">
      <joint joint="left #@i" coef="-0.5"/>
      <joint joint="right #@i" coef="0.5"/>
    </fixed>
@[end for]@
  </tendon>
  <actuator>
@[for i, car in enumerate(cars)]@
    <motor name="forward #@i" tendon="forward #@i" ctrlrange="-4 4"/>
    <motor name="turn #@i" tendon="turn #@i" ctrlrange="-1 1"/>
@[end for]@
  </actuator>
  <sensor>
@[for i, car in enumerate(cars) ]@
    <jointactuatorfrc joint="right #@i" name="right #@i"/>
    <jointactuatorfrc joint="left #@i" name="left #@i"/>
@[for j in range(rangefinders) ]@
    <rangefinder name="rangefinder #@i.#@j" site="rangefinder #@i.#@j"/>
@[end for]@
@[end for]@
@[for i, car in enumerate(cars) ]@
    <gyro name="car #@i gyro" site="car #@i accelerometer"/>
    <accelerometer name="car #@i accelerometer" site="car #@i gyroscope"/>
@[end for]@
  </sensor>
</mujoco>
